Workbook

Sheet TestCase
B1: 대분류 | C1: 중분류 | D1: 소분류 | E1: 테스트 시나리오 | F1: 테스트 조건 | G1: 실행 순서 | H1: Pass Result | I1: P/F | J1: 실제 결과 | K1: 비고 | L1: Tag
A2: =ROW()-2 -> 0 | B2: 게임실행 | C2: 실행 | D2: 게임실행 | E2: 유니티 플레이 버튼을 누른다 | F2: 실행 전 오류가 없을 것 | G2: 1. 메인 씬을 선택한다 2. 메인 씬에서 플레이 버튼을 누른다 | H2: 메인 메뉴에서 게임이 시작된다 | I2: Pass | K2: Pass: 테스트 성공 | L2: =IF(B2="",L1,B2) -> 게임실행 | N2: Pass | O2: Pass: 테스트 성공
A3: =ROW()-2 -> 1 | L3: =IF(B3="",L2,B3) -> 게임실행 | N3: Fail | O3: Fail: 테스트 실패
A4: =ROW()-2 -> 2 | L4: =IF(B4="",L3,B4) -> 게임실행 | N4: Block | O4: Blcok: 상위테스트의 실패 등에 의해 테스트 실행할 수 없음
A5: =ROW()-2 -> 3 | L5: =IF(B5="",L4,B5) -> 게임실행 | N5: N/A | O5: N/A: 환경등의 이유로 테스트 실행 불가능
A6: =ROW()-2 -> 4 | L6: =IF(B6="",L5,B6) -> 게임실행 | N6: N/T | O6: N/T: 테스트 실행되지 않음
A7: =ROW()-2 -> 5 | I7: Pass | L7: =IF(B7="",L6,B7) -> 게임실행
A8: =ROW()-2 -> 6 | B8: 메뉴기능 | C8: 게임메뉴 | D8: 메뉴 선택 | E8: 메인 메뉴에서 지역을 선택한다 | F8: 버튼이 있을 것 | G8: 1. 지역 버튼 클릭 | H8: 인게임 영역이 초기 설정 상태로 재설정 | I8: Pass | L8: =IF(B8="",L7,B8) -> 메뉴기능
A9: =ROW()-2 -> 7 | D9: 미니게임 | G9: 1. 낚시 시작 버튼 클릭 | H9: 1. 낚시 미니게임이 초기 설정으로 재설정 2. 낚시 미니게임 생성 | I9: Pass | L9: =IF(B9="",L8,B9) -> 메뉴기능
A10: =ROW()-2 -> 8 | G10: 1. 스페이스바를 눌러 미니게임 진행 | I10: Pass | L10: =IF(B10="",L9,B10) -> 메뉴기능
A11: =ROW()-2 -> 9 | G11: 1. 노란 부분 밖에 화살표가 있을 때 스페이스바를 눌렀다면 실패 | H11: 1. 실패시 낚시 시작 버튼 생성 2. 초기 설정으로 재설정 | I11: Pass | L11: =IF(B11="",L10,B11) -> 메뉴기능
A12: =ROW()-2 -> 10 | G12: 1. 노란 부분 안에서 화살표가 있을 떄 스페이스바를 누르면 성공 | I12: Pass | L12: =IF(B12="",L11,B12) -> 메뉴기능
A13: =ROW()-2 -> 11 | G13: 1. 낚시 미니게임을 진행하지 않고 놓침 2. 다시 낚시 하기 버튼 클릭 | H13: 1. 낚시 미니게임이 초기 설정으로 재설정 2. 낚시 미니게임 생성 | I13: Fail | J13: 낚시 미니게임이 재설정 및 생성되지 않고 낚시 시작 버튼이 없어짐 | L13: =IF(B13="",L12,B13) -> 메뉴기능
A14: =ROW()-2 -> 12 | G14: 1. 그물 낚시 미니게임을 진행하지 않고 놓침 2. 다시 낚시 하기 버튼 클릭 | H14: 1. 그물 낚시 미니게임이 초기 설정으로 재설정 2. 그물 낚시 미니게임 생성 | I14: Pass | L14: =IF(B14="",L13,B14) -> 메뉴기능
A15: =ROW()-2 -> 13 | G15: 1. 통발 낚시 미니게임 버튼 클릭 | H15: 1. 통발의 대기 시간이 표시됨 2. 시간 종료 시 통발 결과가 생성됨 | I15: Pass | L15: =IF(B15="",L14,B15) -> 메뉴기능
A16: =ROW()-2 -> 14 | D16: 지역 이동 | F16: 지역을 오갈 수 있을 것 | G16: 1. 지역 버튼 클릭 2. 낚시 씬으로 입장 3. 뒤로가기 버튼 클릭 4. 다른 낚시 씬으로 입장 | H16: 1. 입장한 낚시 씬에 맞는 맵 변경 2. 뒤로가기 버튼 클릭 후 맵 선택 화면 입장 3. 입장한 다른 낚시 씬에 맞는 맵 변경 | I16: Pass | L16: =IF(B16="",L15,B16) -> 메뉴기능
A17: =ROW()-2 -> 15 | F17: 지역을 오갈 경우 낚시 미니게임 상태가 초기화 될 것 | G17: 1. 지역 버튼 클릭 2. 낚시 씬으로 입장 3. 낚시 시작 후 뒤로가기 버튼 클릭 4. 다른 낚시 씬으로 입장 5. 이전 맵에서 클릭한 낚시의 미니게임이 활성화되지 않을 것 | H17: 미니게임 영역이 초기 설정 상태로 재설정 | I17: Pass | L17: =IF(B17="",L16,B17) -> 메뉴기능
A18: =ROW()-2 -> 16 | F18: 지역을 오갈 경우 그물 낚시 미니게임 상태가 초기화 될 것 | G18: 1. 지역 버튼 클릭 2. 낚시 씬으로 입장 3. 그물 낚시 시작 후 뒤로가기 버튼 클릭 4. 다른 낚시 씬으로 입장 5. 이전 맵에서 클릭한 그물 낚시의 미니게임이 활성화되지 않을 것 | H18: 미니게임 영역이 초기 설정 상태로 재설정 | I18: Pass | L18: =IF(B18="",L17,B18) -> 메뉴기능
A19: =ROW()-2 -> 17 | F19: 지역을 오갈 경우 통발 낚시 미니게임 상태가 초기화 될 것 | G19: 1. 지역 버튼 클릭 2. 낚시 씬으로 입장 3. 통발 낚시 시작 후 뒤로가기 버튼 클릭 4. 다른 낚시 씬으로 입장 5. 이전 맵에서 클릭한 통발 낚시의 미니게임이 활성화되지 않을 것 | H19: 미니게임 영역이 초기 설정 상태로 재설정 | I19: Fail | J19: 1. 맵 이동 후에도 여전히 통발의 대기 시간이 표시됨 2. 시간 종료 시 통발 결과가 생성됨 | L19: =IF(B19="",L18,B19) -> 메뉴기능
A20: =ROW()-2 -> 18 | D20: 카드 게임 | F20: 카드 게임 진행이 될 것 | G20: 1. 낚시 미니게임 진행 후 카드 게임 버튼 클릭 2. 카드 게임 씬으로 입장 3. AI 적 상대로 카드 게임 진행 | H20: 승리/패배 상황에 따라 각각 승리!/패배 결과 생성 | I20: Pass | L20: =IF(B20="",L19,B20) -> 메뉴기능
A21: =ROW()-2 -> 19 | F21: 카드 게임 씬에서 뒤로가기 기능이 작동될 것 | G21: 1. 낚시 미니게임 진행 후 카드 게임 버튼 클릭 2. 카드 게임 씬으로 입장 3. 뒤로가기 버튼 클릭 | H21: 메뉴 화면으로 복귀 | I21: N/T | J21: 뒤로가기 버튼이 생성되지 않음 | L21: =IF(B21="",L20,B21) -> 메뉴기능
A22: =ROW()-2 -> 20 | L22: =IF(B22="",L21,B22) -> 메뉴기능
A23: =ROW()-2 -> 21 | K23: =IF(B23="",J22,B23)
A24: =ROW()-2 -> 22 | I24: Pass | L24: =IF(B24="",K23,B24)
A25: =ROW()-2 -> 23 | C25: 도움말 메뉴 | L25: =IF(B25="",L24,B25)
A26: =ROW()-2 -> 24 | L26: =IF(B26="",L25,B26)
A27: =ROW()-2 -> 25 | L27: =IF(B27="",L26,B27)
A28: =ROW()-2 -> 26 | L28: =IF(B28="",L27,B28)
A29: =ROW()-2 -> 27 | B29: 인게임기능 | C29: HUD
A30: =ROW()-2 -> 28
A31: =ROW()-2 -> 29
A32: =ROW()-2 -> 30
A33: =ROW()-2 -> 31
A34: =ROW()-2 -> 32
A35: =ROW()-2 -> 33 | C35: 게임 기능
A36: =ROW()-2 -> 34
A37: =ROW()-2 -> 35
A38: =ROW()-2 -> 36
A39: =ROW()-2 -> 37
A40: =ROW()-2 -> 38
...

Sheet TC Map
A1: 테스트케이스 현황
A2: 분류 | B2: 개수 | C2: 비율 | D2: Pass | E2: Fail | F2: N/A | G2: Block | H2: N/T | I2: Total | J2: Total(%)
A3: 게임실행 | B3: =COUNTIF(TestCase!L:L,A3) -> 6 | C3: =IFERROR(B3/$B$6,0) -> 0.28571429 | D3: =COUNTIFS(TestCase!$I:$I,"*"&D$2&"*",TestCase!$L:$L,$A3) -> 0 | E3: =COUNTIFS(TestCase!$I:$I,"*"&E$2&"*",TestCase!$L:$L,$A3) -> 0 | F3: =COUNTIFS(TestCase!$I:$I,"*"&F$2&"*",TestCase!$L:$L,$A3) -> 0 | G3: =COUNTIFS(TestCase!$I:$I,"*"&G$2&"*",TestCase!$L:$L,$A3) -> 0 | H3: =COUNTIFS(TestCase!$I:$I,"*"&H$2&"*",TestCase!$L:$L,$A3) -> 0 | I3: =COUNTIFS(TestCase!$I:$I,"*"&I$2&"*",TestCase!$L:$L,$A3) -> 0 | J3: =I3/B3 -> 0
A4: 메뉴기능 | B4: =COUNTIF(TestCase!L:L,A4) -> 15 | C4: =IFERROR(B4/$B$6,0) -> 0.71428571 | D4: =COUNTIFS(TestCase!$I:$I,"*"&D$2&"*",TestCase!$L:$L,$A4) -> 0 | E4: =COUNTIFS(TestCase!$I:$I,"*"&E$2&"*",TestCase!$L:$L,$A4) -> 0 | F4: =COUNTIFS(TestCase!$I:$I,"*"&F$2&"*",TestCase!$L:$L,$A4) -> 0 | G4: =COUNTIFS(TestCase!$I:$I,"*"&G$2&"*",TestCase!$L:$L,$A4) -> 0 | H4: =COUNTIFS(TestCase!$I:$I,"*"&H$2&"*",TestCase!$L:$L,$A4) -> 0 | I4: =SUM(D4:H4) -> 0 | J4: =I4/B4 -> 0
A5: 인게임기능 | B5: =COUNTIF(TestCase!L:L,A5) -> 0 | C5: =IFERROR(B5/$B$6,0) -> 0 | D5: =COUNTIFS(TestCase!$I:$I,"*"&D$2&"*",TestCase!$L:$L,$A5) -> 0 | E5: =COUNTIFS(TestCase!$I:$I,"*"&E$2&"*",TestCase!$L:$L,$A5) -> 0 | F5: =COUNTIFS(TestCase!$I:$I,"*"&F$2&"*",TestCase!$L:$L,$A5) -> 0 | G5: =COUNTIFS(TestCase!$I:$I,"*"&G$2&"*",TestCase!$L:$L,$A5) -> 0 | H5: =COUNTIFS(TestCase!$I:$I,"*"&H$2&"*",TestCase!$L:$L,$A5) -> 0 | I5: =SUM(D5:H5) -> 0 | J5: =I5/B5 -> #DIV/0!
A6: Total | B6: =SUM(B3:B5) -> 21 | C6: =SUM(C3:C5) -> 1 | D6: =SUM(D3:D5) -> 0 | E6: =SUM(E3:E5) -> 0 | F6: =SUM(F3:F5) -> 0 | G6: =SUM(G3:G5) -> 0 | H6: =SUM(H3:H5) -> 0 | I6: =SUM(I3:I5) -> 0
A7: Total(%) | D7: =D6/$B6 -> 0 | E7: =E6/$B6 -> 0 | F7: =F6/$B6 -> 0 | G7: =G6/$B6 -> 0 | H7: =H6/$B6 -> 0 | I7: =I6/$B6 -> 0
